Workbook

Sheet หลังริม
A1: BOQ สรุปรายการปริมาณงานและราคา บ้านแถวหลังริม
A4: ลำดับที่ | B4: รายการ | C4: จำนวน | D4: หน่วย | E4: ค่าวัสดุ | G4: ค่าแรงงาน | I4: รวมค่าวัสดุและ | J4: หมายเหตุ
E5: ราคาต่อหน่วย | F5: จำนวนเงิน (บาท) | G5: ราคาต่อหน่วย | H5: จำนวนเงิน (บาท) | I5: ค่าแรงงาน (บาท)
A6: 1 | B6: งานโครงสร้างวิศวกรรม
B7: 1.1 งานดิน หิน ทราย และฐานราก
B8: - ขุดดินฐานรากและถมคืน (งานแบ็คโคร) | C8: =10/6 -> 1.6666667 | D8: วัน | E8: 3500 | F8: =E8*C8 -> 5833.3333 | G8: 0 | H8: =G8*C8 -> 0 | I8: =H8+F8 -> 5833.3333
B9: - คอนกรีตผสมเสร็จ 280 กก./ตร.ซม. (ลูกบาศก์) | C9: =5.5/6 -> 0.91666667 | D9: ลบ.ม. | E9: 1500 | F9: =E9*C9 -> 1375 | G9: 0 | H9: =G9*C9 -> 0 | I9: =H9+F9 -> 1375
B10: - คอนกรีตหยาบรองก้นฐานราก 1:3:5 | C10: 0 | D10: ลบ.ม. | E10: 0 | F10: =E10*C10 -> 0 | G10: 0 | H10: =G10*C10 -> 0 | I10: =H10+F10 -> 0
B11: - ทรายถมปรับระดับ | C11: =40/6 -> 6.6666667 | D11: ลบ.ม. | E11: 100 | F11: =E11*C11 -> 666.66667 | G11: 0 | H11: =G11*C11 -> 0 | I11: =H11+F11 -> 666.66667
B12: รวมงานข้อ 1.1 | F12: =SUM(F8:F11) -> 7875 | H12: =SUM(H8:H11) -> 0 | I12: =SUM(I8:I11) -> 7875 | K12: =H12+F12 -> 7875
B13: 1.2 งานตอกเสาเข็ม
B14: - เสาเข็ม ไอตัน ขนาด 0.18 x 0.18 x 16 ม. | C14: =53/6 -> 8.8333333 | D14: ต้น | E14: 2080 | F14: =E14*C14 -> 18373.333 | G14: 750 | H14: =G14*C14 -> 6625 | I14: =H14+F14 -> 24998.333
B15: - ค่าสกัดหัวเสาเข็ม | C15: 0 | D15: ต้น | E15: 0 | F15: =E15*C15 -> 0 | G15: 0 | H15: =G15*C15 -> 0 | I15: =H15+F15 -> 0
B16: รวมงานข้อ 1.2 | F16: =SUM(F14:F15) -> 18373.333 | H16: =SUM(H14:H15) -> 6625 | I16: =SUM(I14:I15) -> 24998.333 | K16: =H16+F16 -> 24998.333
B17: 1.3 งานแบบหล่อคอนกรีต
B18: - ไม้แบบทั่วไป | C18: =20/6 -> 3.3333333 | D18: แผ่น | E18: 590 | F18: =E18*C18 -> 1966.6667 | G18: 0 | H18: =G18*C18 -> 0 | I18: =H18+F18 -> 1966.6667
B19: - ไม้คร่าว | C19: 0 | D19: ลบ.ฟ. | E19: 0 | F19: =E19*C19 -> 0 | G19: 0 | H19: =G19*C19 -> 0 | I19: =H19+F19 -> 0
B20: - ไม้ค้ำยัน | C20: =200/6 -> 33.333333 | D20: ต้น | E20: 25 | F20: =E20*C20 -> 833.33333 | G20: 0 | H20: =G20*C20 -> 0 | I20: =H20+F20 -> 833.33333
B21: - ตะปูขนาดต่างๆ | C21: 0 | D21: กก. | E21: 0 | F21: =E21*C21 -> 0 | G21: 0 | H21: =G21*C21 -> 0 | I21: =H21+F21 -> 0
B22: - ค่าแรงงานไม้แบบ | C22: 0 | D22: ตร.ม. | E22: 0 | F22: =E22*C22 -> 0 | G22: 0 | H22: =G22*C22 -> 0 | I22: =H22+F22 -> 0
B23: รวมงานข้อ 1.3 | F23: =SUM(F18:F22) -> 2800 | H23: =SUM(H18:H22) -> 0 | I23: =SUM(I18:I22) -> 2800 | K23: =H23+F23 -> 2800
B24: 1.4 งานคอนกรีตโครงสร้าง
B25: - คอนกรีตหยาบ( lean) | C25: =15/6 -> 2.5 | D25: ลบ.ม. | E25: 1300 | F25: =E25*C25 -> 3250 | G25: 0 | H25: =G25*C25 -> 0 | I25: =H25+F25 -> 3250
B26: - คอนกรีตผสมเสร็จ 280 กก./ตร.ซม. (ลูกบาศก์) | C26: =55/6 -> 9.1666667 | D26: ลบ.ม. | E26: 1500 | F26: =E26*C26 -> 13750 | G26: 0 | H26: =G26*C26 -> 0 | I26: =H26+F26 -> 13750
B27: - คอนกรีตผสมเสร็จ 320 กก./ตร.ซม. (ลูกบาศก์) | C27: 0 | D27: ลบ.ม. | E27: 1600 | F27: =E27*C27 -> 0 | G27: 0 | H27: =G27*C27 -> 0 | I27: =H27+F27 -> 0
B28: - เหล็กตะแกรง WIRE MESH Ø 6 มม. @ 0.20 ม. (ข้ออ้อย) | C28: =600/6 -> 100 | D28: ตร.ม. | E28: 74.2 | F28: =E28*C28 -> 7420 | G28: 0 | H28: =G28*C28 -> 0 | I28: =H28+F28 -> 7420
B29: - ค่าแรงงานโครงสร้าง | C29: =600/6 -> 100 | D29: ตร.ม. | E29: 0 | F29: =E29*C29 -> 0 | G29: 173.47 | H29: =G29*C29 -> 17347 | I29: =H29+F29 -> 17347
B30: รวมงานข้อ 1.4 | F30: =SUM(F25:F29) -> 24420 | H30: =SUM(H25:H29) -> 17347 | I30: =SUM(I25:I29) -> 41767 | K30: =H30+F30 -> 41767
B31: 1.5 งานเหล็กเสริมคอนกรีต
B32: - เหล็กเส้นกลมผิวเรียบ SR 24 ขนาด Ø 6 มม. | C32: =(50*2.22/1000)/6 -> 0.0185 | D32: ตัน | E32: 64 | F32: =C32*1000/2.22*E32 -> 533.33333 | G32: 0 | H32: =G32*C32 -> 0 | I32: =H32+F32 -> 533.33333
B33: - เหล็กเส้นกลมผิวเรียบ SR 24 ขนาด Ø 9 มม. | C33: =(65*4.99/1000)/6 -> 0.054058333 | D33: ตัน | E33: 137 | F33: =C33*1000/4.99*E33 -> 1484.1667 | G33: 0 | H33: =G33*C33 -> 0 | I33: =H33+F33 -> 1484.1667
B34: - เหล็กเส้นกลมผิวข้ออ้อย SD 40 ขนาด Ø 12 มม. | C34: =(215*8.88/1000)/6 -> 0.3182 | D34: ตัน | E34: 240 | F34: =C34*1000/8.88*E34 -> 8600 | G34: 0 | H34: =G34*C34 -> 0 | I34: =H34+F34 -> 8600
B35: - เหล็กเส้นกลมผิวข้ออ้อย SD 40 ขนาด Ø 16 มม. | C35: 0 | D35: ตัน | E35: 425 | F35: =C35*1000/15.78*E35 -> 0 | G35: 0 | H35: =G35*C35 -> 0 | I35: =H35+F35 -> 0
B36: - ลวดผูกเหล็ก Ø 1.25 มม. (เบอร์ 18) | C36: 0 | D36: กก. | E36: 0 | F36: =E36*C36 -> 0 | G36: 0 | H36: =G36*C36 -> 0 | I36: =H36+F36 -> 0
B37: รวมงานข้อ 1.5 | F37: =SUM(F32:F36) -> 10617.5 | H37: =SUM(H32:H36) -> 0 | I37: =SUM(I32:I36) -> 10617.5 | K37: =H37+F37 -> 10617.5
B38: 1.6 งานผนังสำเร็จ (แบบหล่อพร้อมจับเซี้ยม)
B39: - เหล็กเส้นกลมผิวเรียบ SR 24 ขนาด Ø 9 มม. | C39: =0.299/6 -> 0.049833333 | D39: ตัน | E39: 137 | F39: =C39*1000/4.99*E39 -> 1368.1697 | G39: 0 | H39: =G39*C39 -> 0 | I39: =H39+F39 -> 1368.1697
B40: - เหล็กเส้นกลมผิวข้ออ้อย SD 40 ขนาด Ø 12 มม. | C40: =0.53/6 -> 0.088333333 | D40: ตัน | E40: 240 | F40: =C40*1000/8.88*E40 -> 2387.3874 | G40: 0 | H40: =G40*C40 -> 0 | I40: =H40+F40 -> 2387.3874
B41: - คอนกรีตผสมเสร็จ 280 กก./ตร.ซม. (ปั้ม) | C41: =59/6 -> 9.8333333 | D41: ลบ.ม. | E41: 1600 | F41: =E41*C41 -> 15733.333 | G41: 0 | H41: =G41*C41 -> 0 | I41: =H41+F41 -> 15733.333
B42: - เหล็กตะแกรง WIRE MESH Ø 6 มม. @ 0.20 ม. | C42: =600/6 -> 100 | D42: ตร.ม. | E42: 74.2 | F42: =E42*C42 -> 7420 | G42: 0 | H42: =G42*C42 -> 0 | I42: =H42+F42 -> 7420
...

Sheet จำนวนโครงการ 
B3: โครงการ Nakhon Luang 1 | F3: โครงการ Prime Life Ayutthaya
B5: ลำดับ | C5: รายการ | D5: จำนวนหลัง | F5: ลำดับ | G5: รายการ | H5: จำนวนหลัง
B6: 1 | C6: จัดสรร | D6: ไม่ต้องใส่อะไร ตั้งชื่ออย่างเดียว | F6: 1 | G6: จัดสรร | H6: ไม่ต้องใส่อะไร ตั้งชื่ออย่างเดียว
B7: 2 | C7: ที่ดิน ถมที่ | D7: ไม่ต้องใส่อะไร ตั้งชื่ออย่างเดียว | F7: 2 | G7: ที่ดิน ถมที่ | H7: ไม่ต้องใส่อะไร ตั้งชื่ออย่างเดียว
B8: 3 | C8: แคมป์คนงาน+สโตร์ | D8: ไม่ต้องใส่อะไร ตั้งชื่ออย่างเดียว | F8: 3 | G8: แคมป์คนงาน+สโตร์ | H8: ไม่ต้องใส่อะไร ตั้งชื่ออย่างเดียว
B9: 4 | C9: ค่าเช่าเครื่องจักร | D9: ไม่ต้องใส่อะไร ตั้งชื่ออย่างเดียว | F9: 4 | G9: ค่าเช่าเครื่องจักร | H9: ไม่ต้องใส่อะไร ตั้งชื่ออย่างเดียว
B10: 5 | C10: งาน สาธารณูปโภคโครงการ | D10: ไม่ต้องใส่อะไร ตั้งชื่ออย่างเดียว | F10: 5 | G10: งาน สาธารณูปโภคโครงการ | H10: ไม่ต้องใส่อะไร ตั้งชื่ออย่างเดียว
B11: 6 | C11: รั้ว กำแพง โครงการ | D11: ไม่ต้องใส่อะไร ตั้งชื่ออย่างเดียว | F11: 6 | G11: รั้ว กำแพง โครงการ | H11: ไม่ต้องใส่อะไร ตั้งชื่ออย่างเดียว
B12: 7 | C12: ค่าใช้จ่ายส่วนกลาง | D12: ไม่ต้องใส่อะไร ตั้งชื่ออย่างเดียว | F12: 7 | G12: ค่าใช้จ่ายส่วนกลาง | H12: ไม่ต้องใส่อะไร ตั้งชื่ออย่างเดียว
B13: 8 | C13: ค่าใช้จ่ายธนาคารทั้งหมด | D13: ไม่ต้องใส่อะไร ตั้งชื่ออย่างเดียว | F13: 8 | G13: ค่าใช้จ่ายธนาคารทั้งหมด | H13: ไม่ต้องใส่อะไร ตั้งชื่ออย่างเดียว
B14: 9 | C14: เงินเดือนพนักงาน | D14: ไม่ต้องใส่อะไร ตั้งชื่ออย่างเดียว | F14: 9 | G14: เงินเดือนพนักงาน | H14: ไม่ต้องใส่อะไร ตั้งชื่ออย่างเดียว
B15: 10 | C15: โปรโมชั้น | D15: ไม่ต้องใส่อะไร ตั้งชื่ออย่างเดียว | F15: 10 | G15: โปรโมชั้น | H15: ไม่ต้องใส่อะไร ตั้งชื่ออย่างเดียว
B16: 11 | C16: สำนักงานขาย | D16: ไม่ต้องใส่อะไร ตั้งชื่ออย่างเดียว | F16: 11 | G16: สำนักงานขาย PL | H16: 1
B17: 12 | C17: NL B24 | D17: 4 | F17: 12 | G17: PL B1 | H17: 7
B18: 13 | C18: NL B25 | D18: 4 | F18: 13 | G18: PL B2 | H18: 8
B19: 14 | C19: NL B26 | D19: 4 | F19: 14 | G19: PL B3 | H19: 8
B20: 15 | C20: NL B27 | D20: 4 | F20: 15 | G20: PL B4 | H20: 8
B21: 16 | C21: NL B28 | D21: 4 | F21: 16 | G21: PL B5 | H21: 8
B22: 16 | C22: NL B29
B23: 16 | C23: NL B30 | D23: 4
B24: 17 | C24: NL B31 | D24: 4
B25: 18 | C25: NL B32
B26: 19 | C26: NL B33 | D26: 4
B27: 20 | C27: NL B34 | D27: 4
B28: 21 | C28: NL B35
B29: 22 | C29: NL B36 | D29: 4
B30: 23 | C30: NL B37
B31: 24 | C31: NL B38 | D31: 4

Sheet หลังกลาง
A1: BOQ สรุปรายการปริมาณงานและราคา บ้านแถวหลังกลาง
A4: ลำดับที่ | B4: รายการ | C4: จำนวน | D4: หน่วย | E4: ค่าวัสดุ | G4: ค่าแรงงาน | I4: รวมค่าวัสดุและ | J4: หมายเหตุ
E5: ราคาต่อหน่วย | F5: จำนวนเงิน (บาท) | G5: ราคาต่อหน่วย | H5: จำนวนเงิน (บาท) | I5: ค่าแรงงาน (บาท)
A6: 1 | B6: งานโครงสร้างวิศวกรรม
B7: 1.1 งานดิน หิน ทราย และฐานราก
B8: - ขุดดินฐานรากและถมคืน (งานแบ็คโคร) | C8: =10/6 -> 1.6666667 | D8: วัน | E8: 3500 | F8: =E8*C8 -> 5833.3333 | G8: 0 | H8: =G8*E8 -> 0 | I8: =H8+F8 -> 5833.3333
B9: - คอนกรีตผสมเสร็จ 280 กก./ตร.ซม. (ลูกบาศก์) | C9: =5.5/6 -> 0.91666667 | D9: ลบ.ม. | E9: 1500 | F9: =E9*C9 -> 1375 | G9: 1 | H9: =G9*E9 -> 1500 | I9: =H9+F9 -> 2875
B10: - คอนกรีตหยาบรองก้นฐานราก 1:3:5 | C10: 0 | D10: ลบ.ม. | E10: 0 | F10: =E10*C10 -> 0 | G10: 2 | H10: =G10*E10 -> 0 | I10: =H10+F10 -> 0
B11: - ทรายถมปรับระดับ | C11: =40/6 -> 6.6666667 | D11: ลบ.ม. | E11: 100 | F11: =E11*C11 -> 666.66667 | G11: 3 | H11: =G11*E11 -> 300 | I11: =H11+F11 -> 966.66667
B12: รวมงานข้อ 1.1 | F12: =SUM(F8:F11) -> 7875 | H12: =SUM(H8:H11) -> 1800 | I12: =SUM(I8:I11) -> 9675 | K12: =H12+F12 -> 9675
B13: 1.2 งานตอกเสาเข็ม
B14: - เสาเข็ม ไอตัน ขนาด 0.18 x 0.18 x 16 ม. | C14: =53/6 -> 8.8333333 | D14: ต้น | E14: 2080 | F14: =E14*C14 -> 18373.333 | G14: 750 | H14: =G14*C14 -> 6625 | I14: =H14+F14 -> 24998.333
B15: - ค่าสกัดหัวเสาเข็ม | C15: 0 | D15: ต้น | E15: 0 | F15: =E15*C15 -> 0 | G15: 0 | H15: =G15*C15 -> 0 | I15: =H15+F15 -> 0
B16: รวมงานข้อ 1.2 | F16: =SUM(F14:F15) -> 18373.333 | H16: =SUM(H14:H15) -> 6625 | I16: =SUM(I14:I15) -> 24998.333 | K16: =H16+F16 -> 24998.333
B17: 1.3 งานแบบหล่อคอนกรีต
B18: - ไม้แบบทั่วไป | C18: =20/6 -> 3.3333333 | D18: แผ่น | E18: 590 | F18: =E18*C18 -> 1966.6667 | G18: 0 | H18: =G18*E18 -> 0 | I18: =H18+F18 -> 1966.6667
B19: - ไม้คร่าว | C19: 0 | D19: ลบ.ฟ. | E19: 0 | F19: =E19*C19 -> 0 | G19: 0 | H19: =G19*E19 -> 0 | I19: =H19+F19 -> 0
B20: - ไม้ค้ำยัน | C20: =200/6 -> 33.333333 | D20: ต้น | E20: 25 | F20: =E20*C20 -> 833.33333 | G20: 0 | H20: =G20*E20 -> 0 | I20: =H20+F20 -> 833.33333
B21: - ตะปูขนาดต่างๆ | C21: 0 | D21: กก. | E21: 0 | F21: =E21*C21 -> 0 | G21: 0 | H21: =G21*E21 -> 0 | I21: =H21+F21 -> 0
B22: - ค่าแรงงานไม้แบบ | C22: 0 | D22: ตร.ม. | E22: 0 | F22: =E22*C22 -> 0 | G22: 0 | H22: =G22*E22 -> 0 | I22: =H22+F22 -> 0
B23: รวมงานข้อ 1.3 | F23: =SUM(F18:F22) -> 2800 | H23: =SUM(H18:H22) -> 0 | I23: =SUM(I18:I22) -> 2800 | K23: =H23+F23 -> 2800
B24: 1.4 งานคอนกรีตโครงสร้าง
B25: - คอนกรีตหยาบ( lean) | C25: =15/6 -> 2.5 | D25: ลบ.ม. | E25: 1300 | F25: =E25*C25 -> 3250 | G25: 0 | H25: =G25*C25 -> 0 | I25: =H25+F25 -> 3250
B26: - คอนกรีตผสมเสร็จ 280 กก./ตร.ซม. (ลูกบาศก์) | C26: =55/6 -> 9.1666667 | D26: ลบ.ม. | E26: 1500 | F26: =E26*C26 -> 13750 | G26: 0 | H26: =G26*C26 -> 0 | I26: =H26+F26 -> 13750
B27: - คอนกรีตผสมเสร็จ 320 กก./ตร.ซม. (ลูกบาศก์) | C27: 0 | D27: ลบ.ม. | E27: 1600 | F27: =E27*C27 -> 0 | G27: 0 | H27: =G27*C27 -> 0 | I27: =H27+F27 -> 0
B28: - เหล็กตะแกรง WIRE MESH Ø 6 มม. @ 0.20 ม. (ข้ออ้อย) | C28: =600/6 -> 100 | D28: ตร.ม. | E28: 74.2 | F28: =E28*C28 -> 7420 | G28: 0 | H28: =G28*C28 -> 0 | I28: =H28+F28 -> 7420
B29: - ค่าแรงงานโครงสร้าง | C29: =600/6 -> 100 | D29: ตร.ม. | E29: 0 | F29: =E29*C29 -> 0 | G29: 173.47 | H29: =G29*C29 -> 17347 | I29: =H29+F29 -> 17347
B30: รวมงานข้อ 1.4 | F30: =SUM(F25:F29) -> 24420 | H30: =SUM(H25:H29) -> 17347 | I30: =SUM(I25:I29) -> 41767 | K30: =H30+F30 -> 41767
B31: 1.5 งานเหล็กเสริมคอนกรีต
B32: - เหล็กเส้นกลมผิวเรียบ SR 24 ขนาด Ø 6 มม. | C32: =(50*2.22/1000)/6 -> 0.0185 | D32: ตัน | E32: 64 | F32: =C32*1000/2.22*E32 -> 533.33333 | G32: 0 | H32: =G32*C32 -> 0 | I32: =H32+F32 -> 533.33333
B33: - เหล็กเส้นกลมผิวเรียบ SR 24 ขนาด Ø 9 มม. | C33: =(65*4.99/1000)/6 -> 0.054058333 | D33: ตัน | E33: 137 | F33: =C33*1000/4.99*E33 -> 1484.1667 | G33: 0 | H33: =G33*C33 -> 0 | I33: =H33+F33 -> 1484.1667
B34: - เหล็กเส้นกลมผิวข้ออ้อย SD 40 ขนาด Ø 12 มม. | C34: =(215*8.88/1000)/6 -> 0.3182 | D34: ตัน | E34: 240 | F34: =C34*1000/8.88*E34 -> 8600 | G34: 0 | H34: =G34*C34 -> 0 | I34: =H34+F34 -> 8600
B35: - เหล็กเส้นกลมผิวข้ออ้อย SD 40 ขนาด Ø 16 มม. | C35: 0 | D35: ตัน | E35: 425 | F35: =C35*1000/15.78*E35 -> 0 | G35: 0 | H35: =G35*C35 -> 0 | I35: =H35+F35 -> 0
B36: - ลวดผูกเหล็ก Ø 1.25 มม. (เบอร์ 18) | C36: 0 | D36: กก. | E36: 0 | F36: =E36*C36 -> 0 | G36: 0 | H36: =G36*C36 -> 0 | I36: =H36+F36 -> 0
B37: รวมงานข้อ 1.5 | F37: =SUM(F32:F36) -> 10617.5 | H37: =SUM(H32:H36) -> 0 | I37: =SUM(I32:I36) -> 10617.5 | K37: =H37+F37 -> 10617.5
B38: 1.6 งานผนังสำเร็จ (แบบหล่อพร้อมจับเซี้ยม)
B39: - เหล็กเส้นกลมผิวเรียบ SR 24 ขนาด Ø 9 มม. | C39: =0.299/6 -> 0.049833333 | D39: ตัน | E39: 137 | F39: =C39*1000/4.99*E39 -> 1368.1697 | G39: 0 | H39: =G39*C39 -> 0 | I39: =H39+F39 -> 1368.1697
B40: - เหล็กเส้นกลมผิวข้ออ้อย SD 40 ขนาด Ø 12 มม. | C40: =0.53/6 -> 0.088333333 | D40: ตัน | E40: 240 | F40: =C40*1000/8.88*E40 -> 2387.3874 | G40: 0 | H40: =G40*C40 -> 0 | I40: =H40+F40 -> 2387.3874
B41: - คอนกรีตผสมเสร็จ 280 กก./ตร.ซม. (ปั้ม) | C41: =59/6 -> 9.8333333 | D41: ลบ.ม. | E41: 1600 | F41: =E41*C41 -> 15733.333 | G41: 0 | H41: =G41*C41 -> 0 | I41: =H41+F41 -> 15733.333
B42: - เหล็กตะแกรง WIRE MESH Ø 6 มม. @ 0.20 ม. | C42: =600/6 -> 100 | D42: ตร.ม. | E42: 74.2 | F42: =E42*C42 -> 7420 | G42: 0 | H42: =G42*C42 -> 0 | I42: =H42+F42 -> 7420
...

Sheet บ้านแถว 4 หลังNL
A1: BOQ สรุปรายการปริมาณงานและราคา บ้านแถว 4 หลัง
A4: ลำดับที่ | B4: รายการ | C4: จำนวน | D4: หน่วย | E4: ค่าวัสดุ | G4: ค่าแรงงาน | I4: รวมค่าวัสดุและ | J4: หมายเหตุ
E5: ราคาต่อหน่วย | F5: จำนวนเงิน (บาท) | G5: ราคาต่อหน่วย | H5: จำนวนเงิน (บาท) | I5: ค่าแรงงาน (บาท)
A6: 1 | B6: งานโครงสร้างวิศวกรรม
B7: 1.1 งานดิน หิน ทราย และฐานราก
B8: - ขุดดินฐานรากและถมคืน (งานแบ็คโคร) | C8: =(หลังริม!C8*2)+(หลังกลาง!C8*2) -> 6.6666667 | D8: วัน | E8: 3500 | F8: =E8*C8 -> 23333.333 | G8: 0 | H8: =G8*E8 -> 0 | I8: =H8+F8 -> 23333.333
B9: - คอนกรีตผสมเสร็จ 280 กก./ตร.ซม. (ลูกบาศก์) | C9: =(หลังริม!C9*2)+(หลังกลาง!C9*2) -> 3.6666667 | D9: ลบ.ม. | E9: 1500 | F9: =E9*C9 -> 5500 | G9: 1 | H9: =G9*E9 -> 1500 | I9: =H9+F9 -> 7000
B10: - คอนกรีตหยาบรองก้นฐานราก 1:3:5 | C10: =(หลังริม!C10*2)+(หลังกลาง!C10*2) -> 0 | D10: ลบ.ม. | E10: 0 | F10: =E10*C10 -> 0 | G10: 2 | H10: =G10*E10 -> 0 | I10: =H10+F10 -> 0
B11: - ทรายถมปรับระดับ | C11: =(หลังริม!C11*2)+(หลังกลาง!C11*2) -> 26.666667 | D11: ลบ.ม. | E11: 100 | F11: =E11*C11 -> 2666.6667 | G11: 3 | H11: =G11*E11 -> 300 | I11: =H11+F11 -> 2966.6667
B12: รวมงานข้อ 1.1 | C12: =(หลังริม!C12*2)+(หลังกลาง!C12*2) -> 0 | F12: =SUM(F8:F11) -> 31500 | H12: =SUM(H8:H11) -> 1800 | I12: =SUM(I8:I11) -> 33300 | K12: =H12+F12 -> 33300
B13: 1.2 งานตอกเสาเข็ม | C13: =(หลังริม!C13*2)+(หลังกลาง!C13*2) -> 0
B14: - เสาเข็ม ไอตัน ขนาด 0.18 x 0.18 x 16 ม. | C14: =(หลังริม!C14*2)+(หลังกลาง!C14*2) -> 35.333333 | D14: ต้น | E14: 2080 | F14: =E14*C14 -> 73493.333 | G14: 750 | H14: =G14*C14 -> 26500 | I14: =H14+F14 -> 99993.333
B15: - ค่าสกัดหัวเสาเข็ม | C15: =(หลังริม!C15*2)+(หลังกลาง!C15*2) -> 0 | D15: ต้น | E15: 0 | F15: =E15*C15 -> 0 | G15: 0 | H15: =G15*C15 -> 0 | I15: =H15+F15 -> 0
B16: รวมงานข้อ 1.2 | C16: =(หลังริม!C16*2)+(หลังกลาง!C16*2) -> 0 | F16: =SUM(F14:F15) -> 73493.333 | H16: =SUM(H14:H15) -> 26500 | I16: =SUM(I14:I15) -> 99993.333 | K16: =H16+F16 -> 99993.333
B17: 1.3 งานแบบหล่อคอนกรีต | C17: =(หลังริม!C17*2)+(หลังกลาง!C17*2) -> 0
B18: - ไม้แบบทั่วไป | C18: =(หลังริม!C18*2)+(หลังกลาง!C18*2) -> 13.333333 | D18: แผ่น | E18: 590 | F18: =E18*C18 -> 7866.6667 | G18: 0 | H18: =G18*E18 -> 0 | I18: =H18+F18 -> 7866.6667
B19: - ไม้คร่าว | C19: =(หลังริม!C19*2)+(หลังกลาง!C19*2) -> 0 | D19: ลบ.ฟ. | E19: 0 | F19: =E19*C19 -> 0 | G19: 0 | H19: =G19*E19 -> 0 | I19: =H19+F19 -> 0
B20: - ไม้ค้ำยัน | C20: =(หลังริม!C20*2)+(หลังกลาง!C20*2) -> 133.33333 | D20: ต้น | E20: 25 | F20: =E20*C20 -> 3333.3333 | G20: 0 | H20: =G20*E20 -> 0 | I20: =H20+F20 -> 3333.3333
B21: - ตะปูขนาดต่างๆ | C21: =(หลังริม!C21*2)+(หลังกลาง!C21*2) -> 0 | D21: กก. | E21: 0 | F21: =E21*C21 -> 0 | G21: 0 | H21: =G21*E21 -> 0 | I21: =H21+F21 -> 0
B22: - ค่าแรงงานไม้แบบ | C22: =(หลังริม!C22*2)+(หลังกลาง!C22*2) -> 0 | D22: ตร.ม. | E22: 0 | F22: =E22*C22 -> 0 | G22: 0 | H22: =G22*E22 -> 0 | I22: =H22+F22 -> 0
B23: รวมงานข้อ 1.3 | C23: =(หลังริม!C23*2)+(หลังกลาง!C23*2) -> 0 | F23: =SUM(F18:F22) -> 11200 | H23: =SUM(H18:H22) -> 0 | I23: =SUM(I18:I22) -> 11200 | K23: =H23+F23 -> 11200
B24: 1.4 งานคอนกรีตโครงสร้าง | C24: =(หลังริม!C24*2)+(หลังกลาง!C24*2) -> 0
B25: - คอนกรีตหยาบ( lean) | C25: =(หลังริม!C25*2)+(หลังกลาง!C25*2) -> 10 | D25: ลบ.ม. | E25: 1300 | F25: =E25*C25 -> 13000 | G25: 0 | H25: =G25*C25 -> 0 | I25: =H25+F25 -> 13000
B26: - คอนกรีตผสมเสร็จ 280 กก./ตร.ซม. (ลูกบาศก์) | C26: =(หลังริม!C26*2)+(หลังกลาง!C26*2) -> 36.666667 | D26: ลบ.ม. | E26: 1500 | F26: =E26*C26 -> 55000 | G26: 0 | H26: =G26*C26 -> 0 | I26: =H26+F26 -> 55000
B27: - คอนกรีตผสมเสร็จ 320 กก./ตร.ซม. (ลูกบาศก์) | C27: =(หลังริม!C27*2)+(หลังกลาง!C27*2) -> 0 | D27: ลบ.ม. | E27: 1600 | F27: =E27*C27 -> 0 | G27: 0 | H27: =G27*C27 -> 0 | I27: =H27+F27 -> 0
B28: - เหล็กตะแกรง WIRE MESH Ø 6 มม. @ 0.20 ม. (ข้ออ้อย) | C28: =(หลังริม!C28*2)+(หลังกลาง!C28*2) -> 400 | D28: ตร.ม. | E28: 74.2 | F28: =E28*C28 -> 29680 | G28: 0 | H28: =G28*C28 -> 0 | I28: =H28+F28 -> 29680
B29: - ค่าแรงงานโครงสร้าง | C29: =(หลังริม!C29*2)+(หลังกลาง!C29*2) -> 400 | D29: ตร.ม. | E29: 0 | F29: =E29*C29 -> 0 | G29: 173.47 | H29: =G29*C29 -> 69388 | I29: =H29+F29 -> 69388
B30: รวมงานข้อ 1.4 | C30: =(หลังริม!C30*2)+(หลังกลาง!C30*2) -> 0 | F30: =SUM(F25:F29) -> 97680 | H30: =SUM(H25:H29) -> 69388 | I30: =SUM(I25:I29) -> 167068 | K30: =H30+F30 -> 167068
B31: 1.5 งานเหล็กเสริมคอนกรีต | C31: =(หลังริม!C31*2)+(หลังกลาง!C31*2) -> 0
B32: - เหล็กเส้นกลมผิวเรียบ SR 24 ขนาด Ø 6 มม. | C32: =(หลังริม!C32*2)+(หลังกลาง!C32*2) -> 0.074 | D32: ตัน | E32: 64 | F32: =C32*1000/2.22*E32 -> 2133.3333 | G32: 0 | H32: =G32*C32 -> 0 | I32: =H32+F32 -> 2133.3333
B33: - เหล็กเส้นกลมผิวเรียบ SR 24 ขนาด Ø 9 มม. | C33: =(หลังริม!C33*2)+(หลังกลาง!C33*2) -> 0.21623333 | D33: ตัน | E33: 137 | F33: =C33*1000/4.99*E33 -> 5936.6667 | G33: 0 | H33: =G33*C33 -> 0 | I33: =H33+F33 -> 5936.6667
B34: - เหล็กเส้นกลมผิวข้ออ้อย SD 40 ขนาด Ø 12 มม. | C34: =(หลังริม!C34*2)+(หลังกลาง!C34*2) -> 1.2728 | D34: ตัน | E34: 240 | F34: =C34*1000/8.88*E34 -> 34400 | G34: 0 | H34: =G34*C34 -> 0 | I34: =H34+F34 -> 34400
B35: - เหล็กเส้นกลมผิวข้ออ้อย SD 40 ขนาด Ø 16 มม. | C35: =(หลังริม!C35*2)+(หลังกลาง!C35*2) -> 0 | D35: ตัน | E35: 425 | F35: =C35*1000/15.78*E35 -> 0 | G35: 0 | H35: =G35*C35 -> 0 | I35: =H35+F35 -> 0
B36: - ลวดผูกเหล็ก Ø 1.25 มม. (เบอร์ 18) | C36: =(หลังริม!C36*2)+(หลังกลาง!C36*2) -> 0 | D36: กก. | E36: 0 | F36: =E36*C36 -> 0 | G36: 0 | H36: =G36*C36 -> 0 | I36: =H36+F36 -> 0
B37: รวมงานข้อ 1.5 | C37: =(หลังริม!C37*2)+(หลังกลาง!C37*2) -> 0 | F37: =SUM(F32:F36) -> 42470 | H37: =SUM(H32:H36) -> 0 | I37: =SUM(I32:I36) -> 42470 | K37: =H37+F37 -> 42470
B38: 1.6 งานผนังสำเร็จ (แบบหล่อพร้อมจับเซี้ยม) | C38: =(หลังริม!C38*2)+(หลังกลาง!C38*2) -> 0
B39: - เหล็กเส้นกลมผิวเรียบ SR 24 ขนาด Ø 9 มม. | C39: =(หลังริม!C39*2)+(หลังกลาง!C39*2) -> 0.19933333 | D39: ตัน | E39: 137 | F39: =C39*1000/4.99*E39 -> 5472.6787 | G39: 0 | H39: =G39*C39 -> 0 | I39: =H39+F39 -> 5472.6787
B40: - เหล็กเส้นกลมผิวข้ออ้อย SD 40 ขนาด Ø 12 มม. | C40: =(หลังริม!C40*2)+(หลังกลาง!C40*2) -> 0.35333333 | D40: ตัน | E40: 240 | F40: =C40*1000/8.88*E40 -> 9549.5495 | G40: 0 | H40: =G40*C40 -> 0 | I40: =H40+F40 -> 9549.5495
B41: - คอนกรีตผสมเสร็จ 280 กก./ตร.ซม. (ปั้ม) | C41: =(หลังริม!C41*2)+(หลังกลาง!C41*2) -> 39.333333 | D41: ลบ.ม. | E41: 1600 | F41: =E41*C41 -> 62933.333 | G41: 0 | H41: =G41*C41 -> 0 | I41: =H41+F41 -> 62933.333
B42: - เหล็กตะแกรง WIRE MESH Ø 6 มม. @ 0.20 ม. | C42: =(หลังริม!C42*2)+(หลังกลาง!C42*2) -> 400 | D42: ตร.ม. | E42: 74.2 | F42: =E42*C42 -> 29680 | G42: 0 | H42: =G42*C42 -> 0 | I42: =H42+F42 -> 29680
...

Sheet บ้านแถว 6 หลัง
A1: BOQ สรุปรายการปริมาณงานและราคา บ้านแถว 6 หลัง
A4: ลำดับที่ | B4: รายการ | C4: จำนวน | D4: หน่วย | E4: ค่าวัสดุ | G4: ค่าแรงงาน | I4: รวมค่าวัสดุและ | J4: หมายเหตุ
E5: ราคาต่อหน่วย | F5: จำนวนเงิน (บาท) | G5: ราคาต่อหน่วย | H5: จำนวนเงิน (บาท) | I5: ค่าแรงงาน (บาท)
A6: 1 | B6: งานโครงสร้างวิศวกรรม
B7: 1.1 งานดิน หิน ทราย และฐานราก
B8: - ขุดดินฐานรากและถมคืน (งานแบ็คโคร) | C8: =(หลังริม!C8*2)+(หลังกลาง!C8*4) -> 10 | D8: วัน | E8: 3500 | F8: =E8*C8 -> 35000 | G8: 0 | H8: =G8*E8 -> 0 | I8: =H8+F8 -> 35000
B9: - คอนกรีตผสมเสร็จ 280 กก./ตร.ซม. (ลูกบาศก์) | C9: =(หลังริม!C9*2)+(หลังกลาง!C9*4) -> 5.5 | D9: ลบ.ม. | E9: 1500 | F9: =E9*C9 -> 8250 | G9: 1 | H9: =G9*E9 -> 1500 | I9: =H9+F9 -> 9750
B10: - คอนกรีตหยาบรองก้นฐานราก 1:3:5 | C10: =(หลังริม!C10*2)+(หลังกลาง!C10*4) -> 0 | D10: ลบ.ม. | E10: 0 | F10: =E10*C10 -> 0 | G10: 2 | H10: =G10*E10 -> 0 | I10: =H10+F10 -> 0
B11: - ทรายถมปรับระดับ | C11: =(หลังริม!C11*2)+(หลังกลาง!C11*4) -> 40 | D11: ลบ.ม. | E11: 100 | F11: =E11*C11 -> 4000 | G11: 3 | H11: =G11*E11 -> 300 | I11: =H11+F11 -> 4300
B12: รวมงานข้อ 1.1 | C12: =(หลังริม!C12*2)+(หลังกลาง!C12*4) -> 0 | F12: =SUM(F8:F11) -> 47250 | H12: =SUM(H8:H11) -> 1800 | I12: =SUM(I8:I11) -> 49050 | K12: =H12+F12 -> 49050
B13: 1.2 งานตอกเสาเข็ม | C13: =(หลังริม!C13*2)+(หลังกลาง!C13*4) -> 0
B14: - เสาเข็ม ไอตัน ขนาด 0.18 x 0.18 x 16 ม. | C14: =(หลังริม!C14*2)+(หลังกลาง!C14*4) -> 53 | D14: ต้น | E14: 2080 | F14: =E14*C14 -> 110240 | G14: 750 | H14: =G14*C14 -> 39750 | I14: =H14+F14 -> 149990
B15: - ค่าสกัดหัวเสาเข็ม | C15: =(หลังริม!C15*2)+(หลังกลาง!C15*4) -> 0 | D15: ต้น | E15: 0 | F15: =E15*C15 -> 0 | G15: 0 | H15: =G15*C15 -> 0 | I15: =H15+F15 -> 0
B16: รวมงานข้อ 1.2 | C16: =(หลังริม!C16*2)+(หลังกลาง!C16*4) -> 0 | F16: =SUM(F14:F15) -> 110240 | H16: =SUM(H14:H15) -> 39750 | I16: =SUM(I14:I15) -> 149990 | K16: =H16+F16 -> 149990
B17: 1.3 งานแบบหล่อคอนกรีต | C17: =(หลังริม!C17*2)+(หลังกลาง!C17*4) -> 0
B18: - ไม้แบบทั่วไป | C18: =(หลังริม!C18*2)+(หลังกลาง!C18*4) -> 20 | D18: แผ่น | E18: 590 | F18: =E18*C18 -> 11800 | G18: 0 | H18: =G18*E18 -> 0 | I18: =H18+F18 -> 11800
B19: - ไม้คร่าว | C19: =(หลังริม!C19*2)+(หลังกลาง!C19*4) -> 0 | D19: ลบ.ฟ. | E19: 0 | F19: =E19*C19 -> 0 | G19: 0 | H19: =G19*E19 -> 0 | I19: =H19+F19 -> 0
B20: - ไม้ค้ำยัน | C20: =(หลังริม!C20*2)+(หลังกลาง!C20*4) -> 200 | D20: ต้น | E20: 25 | F20: =E20*C20 -> 5000 | G20: 0 | H20: =G20*E20 -> 0 | I20: =H20+F20 -> 5000
B21: - ตะปูขนาดต่างๆ | C21: =(หลังริม!C21*2)+(หลังกลาง!C21*4) -> 0 | D21: กก. | E21: 0 | F21: =E21*C21 -> 0 | G21: 0 | H21: =G21*E21 -> 0 | I21: =H21+F21 -> 0
B22: - ค่าแรงงานไม้แบบ | C22: =(หลังริม!C22*2)+(หลังกลาง!C22*4) -> 0 | D22: ตร.ม. | E22: 0 | F22: =E22*C22 -> 0 | G22: 0 | H22: =G22*E22 -> 0 | I22: =H22+F22 -> 0
B23: รวมงานข้อ 1.3 | C23: =(หลังริม!C23*2)+(หลังกลาง!C23*4) -> 0 | F23: =SUM(F18:F22) -> 16800 | H23: =SUM(H18:H22) -> 0 | I23: =SUM(I18:I22) -> 16800 | K23: =H23+F23 -> 16800
B24: 1.4 งานคอนกรีตโครงสร้าง | C24: =(หลังริม!C24*2)+(หลังกลาง!C24*4) -> 0
B25: - คอนกรีตหยาบ( lean) | C25: =(หลังริม!C25*2)+(หลังกลาง!C25*4) -> 15 | D25: ลบ.ม. | E25: 1300 | F25: =E25*C25 -> 19500 | G25: 0 | H25: =G25*C25 -> 0 | I25: =H25+F25 -> 19500
B26: - คอนกรีตผสมเสร็จ 280 กก./ตร.ซม. (ลูกบาศก์) | C26: =(หลังริม!C26*2)+(หลังกลาง!C26*4) -> 55 | D26: ลบ.ม. | E26: 1500 | F26: =E26*C26 -> 82500 | G26: 0 | H26: =G26*C26 -> 0 | I26: =H26+F26 -> 82500
B27: - คอนกรีตผสมเสร็จ 320 กก./ตร.ซม. (ลูกบาศก์) | C27: =(หลังริม!C27*2)+(หลังกลาง!C27*4) -> 0 | D27: ลบ.ม. | E27: 1600 | F27: =E27*C27 -> 0 | G27: 0 | H27: =G27*C27 -> 0 | I27: =H27+F27 -> 0
B28: - เหล็กตะแกรง WIRE MESH Ø 6 มม. @ 0.20 ม. (ข้ออ้อย) | C28: =(หลังริม!C28*2)+(หลังกลาง!C28*4) -> 600 | D28: ตร.ม. | E28: 74.2 | F28: =E28*C28 -> 44520 | G28: 0 | H28: =G28*C28 -> 0 | I28: =H28+F28 -> 44520
B29: - ค่าแรงงานโครงสร้าง | C29: =(หลังริม!C29*2)+(หลังกลาง!C29*4) -> 600 | D29: ตร.ม. | E29: 0 | F29: =E29*C29 -> 0 | G29: 173.47 | H29: =G29*C29 -> 104082 | I29: =H29+F29 -> 104082
B30: รวมงานข้อ 1.4 | C30: =(หลังริม!C30*2)+(หลังกลาง!C30*4) -> 0 | F30: =SUM(F25:F29) -> 146520 | H30: =SUM(H25:H29) -> 104082 | I30: =SUM(I25:I29) -> 250602 | K30: =H30+F30 -> 250602
B31: 1.5 งานเหล็กเสริมคอนกรีต | C31: =(หลังริม!C31*2)+(หลังกลาง!C31*4) -> 0
B32: - เหล็กเส้นกลมผิวเรียบ SR 24 ขนาด Ø 6 มม. | C32: =(หลังริม!C32*2)+(หลังกลาง!C32*4) -> 0.111 | D32: ตัน | E32: 64 | F32: =C32*1000/2.22*E32 -> 3200 | G32: 0 | H32: =G32*C32 -> 0 | I32: =H32+F32 -> 3200
B33: - เหล็กเส้นกลมผิวเรียบ SR 24 ขนาด Ø 9 มม. | C33: =(หลังริม!C33*2)+(หลังกลาง!C33*4) -> 0.32435 | D33: ตัน | E33: 137 | F33: =C33*1000/4.99*E33 -> 8905 | G33: 0 | H33: =G33*C33 -> 0 | I33: =H33+F33 -> 8905
B34: - เหล็กเส้นกลมผิวข้ออ้อย SD 40 ขนาด Ø 12 มม. | C34: =(หลังริม!C34*2)+(หลังกลาง!C34*4) -> 1.9092 | D34: ตัน | E34: 240 | F34: =C34*1000/8.88*E34 -> 51600 | G34: 0 | H34: =G34*C34 -> 0 | I34: =H34+F34 -> 51600
B35: - เหล็กเส้นกลมผิวข้ออ้อย SD 40 ขนาด Ø 16 มม. | C35: =(หลังริม!C35*2)+(หลังกลาง!C35*4) -> 0 | D35: ตัน | E35: 425 | F35: =C35*1000/15.78*E35 -> 0 | G35: 0 | H35: =G35*C35 -> 0 | I35: =H35+F35 -> 0
B36: - ลวดผูกเหล็ก Ø 1.25 มม. (เบอร์ 18) | C36: =(หลังริม!C36*2)+(หลังกลาง!C36*4) -> 0 | D36: กก. | E36: 0 | F36: =E36*C36 -> 0 | G36: 0 | H36: =G36*C36 -> 0 | I36: =H36+F36 -> 0
B37: รวมงานข้อ 1.5 | C37: =(หลังริม!C37*2)+(หลังกลาง!C37*4) -> 0 | F37: =SUM(F32:F36) -> 63705 | H37: =SUM(H32:H36) -> 0 | I37: =SUM(I32:I36) -> 63705 | K37: =H37+F37 -> 63705
B38: 1.6 งานผนังสำเร็จ (แบบหล่อพร้อมจับเซี้ยม) | C38: =(หลังริม!C38*2)+(หลังกลาง!C38*4) -> 0
B39: - เหล็กเส้นกลมผิวเรียบ SR 24 ขนาด Ø 9 มม. | C39: =(หลังริม!C39*2)+(หลังกลาง!C39*4) -> 0.299 | D39: ตัน | E39: 137 | F39: =C39*1000/4.99*E39 -> 8209.018 | G39: 0 | H39: =G39*C39 -> 0 | I39: =H39+F39 -> 8209.018
B40: - เหล็กเส้นกลมผิวข้ออ้อย SD 40 ขนาด Ø 12 มม. | C40: =(หลังริม!C40*2)+(หลังกลาง!C40*4) -> 0.53 | D40: ตัน | E40: 240 | F40: =C40*1000/8.88*E40 -> 14324.324 | G40: 0 | H40: =G40*C40 -> 0 | I40: =H40+F40 -> 14324.324
B41: - คอนกรีตผสมเสร็จ 280 กก./ตร.ซม. (ปั้ม) | C41: =(หลังริม!C41*2)+(หลังกลาง!C41*4) -> 59 | D41: ลบ.ม. | E41: 1600 | F41: =E41*C41 -> 94400 | G41: 0 | H41: =G41*C41 -> 0 | I41: =H41+F41 -> 94400
B42: - เหล็กตะแกรง WIRE MESH Ø 6 มม. @ 0.20 ม. | C42: =(หลังริม!C42*2)+(หลังกลาง!C42*4) -> 600 | D42: ตร.ม. | E42: 74.2 | F42: =E42*C42 -> 44520 | G42: 0 | H42: =G42*C42 -> 0 | I42: =H42+F42 -> 44520
...

Sheet บ้านแถว 8 หลังPL
A1: BOQ สรุปรายการปริมาณงานและราคา บ้านแถว 6 หลัง
A4: ลำดับที่ | B4: รายการ | C4: จำนวน | D4: หน่วย | E4: ค่าวัสดุ | G4: ค่าแรงงาน | I4: รวมค่าวัสดุและ | J4: หมายเหตุ
E5: ราคาต่อหน่วย | F5: จำนวนเงิน (บาท) | G5: ราคาต่อหน่วย | H5: จำนวนเงิน (บาท) | I5: ค่าแรงงาน (บาท)
A6: 1 | B6: งานโครงสร้างวิศวกรรม
B7: 1.1 งานดิน หิน ทราย และฐานราก
B8: - ขุดดินฐานรากและถมคืน (งานแบ็คโคร) | C8: =(หลังริม!C8*2)+(หลังกลาง!C8*6) -> 13.333333 | D8: วัน | E8: 3500 | F8: =E8*C8 -> 46666.667 | G8: 0 | H8: =G8*E8 -> 0 | I8: =H8+F8 -> 46666.667
B9: - คอนกรีตผสมเสร็จ 280 กก./ตร.ซม. (ลูกบาศก์) | C9: =(หลังริม!C9*2)+(หลังกลาง!C9*6) -> 7.3333333 | D9: ลบ.ม. | E9: 1500 | F9: =E9*C9 -> 11000 | G9: 1 | H9: =G9*E9 -> 1500 | I9: =H9+F9 -> 12500
B10: - คอนกรีตหยาบรองก้นฐานราก 1:3:5 | C10: =(หลังริม!C10*2)+(หลังกลาง!C10*6) -> 0 | D10: ลบ.ม. | E10: 0 | F10: =E10*C10 -> 0 | G10: 2 | H10: =G10*E10 -> 0 | I10: =H10+F10 -> 0
B11: - ทรายถมปรับระดับ | C11: =(หลังริม!C11*2)+(หลังกลาง!C11*6) -> 53.333333 | D11: ลบ.ม. | E11: 100 | F11: =E11*C11 -> 5333.3333 | G11: 3 | H11: =G11*E11 -> 300 | I11: =H11+F11 -> 5633.3333
B12: รวมงานข้อ 1.1 | C12: =(หลังริม!C12*2)+(หลังกลาง!C12*6) -> 0 | F12: =SUM(F8:F11) -> 63000 | H12: =SUM(H8:H11) -> 1800 | I12: =SUM(I8:I11) -> 64800 | K12: =H12+F12 -> 64800
B13: 1.2 งานตอกเสาเข็ม | C13: =(หลังริม!C13*2)+(หลังกลาง!C13*6) -> 0
B14: - เสาเข็ม ไอตัน ขนาด 0.18 x 0.18 x 16 ม. | C14: =(หลังริม!C14*2)+(หลังกลาง!C14*6) -> 70.666667 | D14: ต้น | E14: 2080 | F14: =E14*C14 -> 146986.67 | G14: 750 | H14: =G14*C14 -> 53000 | I14: =H14+F14 -> 199986.67
B15: - ค่าสกัดหัวเสาเข็ม | C15: =(หลังริม!C15*2)+(หลังกลาง!C15*6) -> 0 | D15: ต้น | E15: 0 | F15: =E15*C15 -> 0 | G15: 0 | H15: =G15*C15 -> 0 | I15: =H15+F15 -> 0
B16: รวมงานข้อ 1.2 | C16: =(หลังริม!C16*2)+(หลังกลาง!C16*6) -> 0 | F16: =SUM(F14:F15) -> 146986.67 | H16: =SUM(H14:H15) -> 53000 | I16: =SUM(I14:I15) -> 199986.67 | K16: =H16+F16 -> 199986.67
B17: 1.3 งานแบบหล่อคอนกรีต | C17: =(หลังริม!C17*2)+(หลังกลาง!C17*6) -> 0
B18: - ไม้แบบทั่วไป | C18: =(หลังริม!C18*2)+(หลังกลาง!C18*6) -> 26.666667 | D18: แผ่น | E18: 590 | F18: =E18*C18 -> 15733.333 | G18: 0 | H18: =G18*E18 -> 0 | I18: =H18+F18 -> 15733.333
B19: - ไม้คร่าว | C19: =(หลังริม!C19*2)+(หลังกลาง!C19*6) -> 0 | D19: ลบ.ฟ. | E19: 0 | F19: =E19*C19 -> 0 | G19: 0 | H19: =G19*E19 -> 0 | I19: =H19+F19 -> 0
B20: - ไม้ค้ำยัน | C20: =(หลังริม!C20*2)+(หลังกลาง!C20*6) -> 266.66667 | D20: ต้น | E20: 25 | F20: =E20*C20 -> 6666.6667 | G20: 0 | H20: =G20*E20 -> 0 | I20: =H20+F20 -> 6666.6667
B21: - ตะปูขนาดต่างๆ | C21: =(หลังริม!C21*2)+(หลังกลาง!C21*6) -> 0 | D21: กก. | E21: 0 | F21: =E21*C21 -> 0 | G21: 0 | H21: =G21*E21 -> 0 | I21: =H21+F21 -> 0
B22: - ค่าแรงงานไม้แบบ | C22: =(หลังริม!C22*2)+(หลังกลาง!C22*6) -> 0 | D22: ตร.ม. | E22: 0 | F22: =E22*C22 -> 0 | G22: 0 | H22: =G22*E22 -> 0 | I22: =H22+F22 -> 0
B23: รวมงานข้อ 1.3 | C23: =(หลังริม!C23*2)+(หลังกลาง!C23*6) -> 0 | F23: =SUM(F18:F22) -> 22400 | H23: =SUM(H18:H22) -> 0 | I23: =SUM(I18:I22) -> 22400 | K23: =H23+F23 -> 22400
B24: 1.4 งานคอนกรีตโครงสร้าง | C24: =(หลังริม!C24*2)+(หลังกลาง!C24*6) -> 0
B25: - คอนกรีตหยาบ( lean) | C25: =(หลังริม!C25*2)+(หลังกลาง!C25*6) -> 20 | D25: ลบ.ม. | E25: 1300 | F25: =E25*C25 -> 26000 | G25: 0 | H25: =G25*C25 -> 0 | I25: =H25+F25 -> 26000
B26: - คอนกรีตผสมเสร็จ 280 กก./ตร.ซม. (ลูกบาศก์) | C26: =(หลังริม!C26*2)+(หลังกลาง!C26*6) -> 73.333333 | D26: ลบ.ม. | E26: 1500 | F26: =E26*C26 -> 110000 | G26: 0 | H26: =G26*C26 -> 0 | I26: =H26+F26 -> 110000
B27: - คอนกรีตผสมเสร็จ 320 กก./ตร.ซม. (ลูกบาศก์) | C27: =(หลังริม!C27*2)+(หลังกลาง!C27*6) -> 0 | D27: ลบ.ม. | E27: 1600 | F27: =E27*C27 -> 0 | G27: 0 | H27: =G27*C27 -> 0 | I27: =H27+F27 -> 0
B28: - เหล็กตะแกรง WIRE MESH Ø 6 มม. @ 0.20 ม. (ข้ออ้อย) | C28: =(หลังริม!C28*2)+(หลังกลาง!C28*6) -> 800 | D28: ตร.ม. | E28: 74.2 | F28: =E28*C28 -> 59360 | G28: 0 | H28: =G28*C28 -> 0 | I28: =H28+F28 -> 59360
B29: - ค่าแรงงานโครงสร้าง | C29: =(หลังริม!C29*2)+(หลังกลาง!C29*6) -> 800 | D29: ตร.ม. | E29: 0 | F29: =E29*C29 -> 0 | G29: 173.47 | H29: =G29*C29 -> 138776 | I29: =H29+F29 -> 138776
B30: รวมงานข้อ 1.4 | C30: =(หลังริม!C30*2)+(หลังกลาง!C30*6) -> 0 | F30: =SUM(F25:F29) -> 195360 | H30: =SUM(H25:H29) -> 138776 | I30: =SUM(I25:I29) -> 334136 | K30: =H30+F30 -> 334136
B31: 1.5 งานเหล็กเสริมคอนกรีต | C31: =(หลังริม!C31*2)+(หลังกลาง!C31*6) -> 0
B32: - เหล็กเส้นกลมผิวเรียบ SR 24 ขนาด Ø 6 มม. | C32: =(หลังริม!C32*2)+(หลังกลาง!C32*6) -> 0.148 | D32: ตัน | E32: 64 | F32: =C32*1000/2.22*E32 -> 4266.6667 | G32: 0 | H32: =G32*C32 -> 0 | I32: =H32+F32 -> 4266.6667
B33: - เหล็กเส้นกลมผิวเรียบ SR 24 ขนาด Ø 9 มม. | C33: =(หลังริม!C33*2)+(หลังกลาง!C33*6) -> 0.43246667 | D33: ตัน | E33: 137 | F33: =C33*1000/4.99*E33 -> 11873.333 | G33: 0 | H33: =G33*C33 -> 0 | I33: =H33+F33 -> 11873.333
B34: - เหล็กเส้นกลมผิวข้ออ้อย SD 40 ขนาด Ø 12 มม. | C34: =(หลังริม!C34*2)+(หลังกลาง!C34*6) -> 2.5456 | D34: ตัน | E34: 240 | F34: =C34*1000/8.88*E34 -> 68800 | G34: 0 | H34: =G34*C34 -> 0 | I34: =H34+F34 -> 68800
B35: - เหล็กเส้นกลมผิวข้ออ้อย SD 40 ขนาด Ø 16 มม. | C35: =(หลังริม!C35*2)+(หลังกลาง!C35*6) -> 0 | D35: ตัน | E35: 425 | F35: =C35*1000/15.78*E35 -> 0 | G35: 0 | H35: =G35*C35 -> 0 | I35: =H35+F35 -> 0
B36: - ลวดผูกเหล็ก Ø 1.25 มม. (เบอร์ 18) | C36: =(หลังริม!C36*2)+(หลังกลาง!C36*6) -> 0 | D36: กก. | E36: 0 | F36: =E36*C36 -> 0 | G36: 0 | H36: =G36*C36 -> 0 | I36: =H36+F36 -> 0
B37: รวมงานข้อ 1.5 | C37: =(หลังริม!C37*2)+(หลังกลาง!C37*6) -> 0 | F37: =SUM(F32:F36) -> 84940 | H37: =SUM(H32:H36) -> 0 | I37: =SUM(I32:I36) -> 84940 | K37: =H37+F37 -> 84940
B38: 1.6 งานผนังสำเร็จ (แบบหล่อพร้อมจับเซี้ยม) | C38: =(หลังริม!C38*2)+(หลังกลาง!C38*6) -> 0
B39: - เหล็กเส้นกลมผิวเรียบ SR 24 ขนาด Ø 9 มม. | C39: =(หลังริม!C39*2)+(หลังกลาง!C39*6) -> 0.39866667 | D39: ตัน | E39: 137 | F39: =C39*1000/4.99*E39 -> 10945.357 | G39: 0 | H39: =G39*C39 -> 0 | I39: =H39+F39 -> 10945.357
B40: - เหล็กเส้นกลมผิวข้ออ้อย SD 40 ขนาด Ø 12 มม. | C40: =(หลังริม!C40*2)+(หลังกลาง!C40*6) -> 0.70666667 | D40: ตัน | E40: 240 | F40: =C40*1000/8.88*E40 -> 19099.099 | G40: 0 | H40: =G40*C40 -> 0 | I40: =H40+F40 -> 19099.099
B41: - คอนกรีตผสมเสร็จ 280 กก./ตร.ซม. (ปั้ม) | C41: =(หลังริม!C41*2)+(หลังกลาง!C41*6) -> 78.666667 | D41: ลบ.ม. | E41: 1600 | F41: =E41*C41 -> 125866.67 | G41: 0 | H41: =G41*C41 -> 0 | I41: =H41+F41 -> 125866.67
B42: - เหล็กตะแกรง WIRE MESH Ø 6 มม. @ 0.20 ม. | C42: =(หลังริม!C42*2)+(หลังกลาง!C42*6) -> 800 | D42: ตร.ม. | E42: 74.2 | F42: =E42*C42 -> 59360 | G42: 0 | H42: =G42*C42 -> 0 | I42: =H42+F42 -> 59360
...

Sheet บ้านแถว 7 หลังPL
A1: BOQ สรุปรายการปริมาณงานและราคา บ้านแถว 6 หลัง
A4: ลำดับที่ | B4: รายการ | C4: จำนวน | D4: หน่วย | E4: ค่าวัสดุ | G4: ค่าแรงงาน | I4: รวมค่าวัสดุและ | J4: หมายเหตุ
E5: ราคาต่อหน่วย | F5: จำนวนเงิน (บาท) | G5: ราคาต่อหน่วย | H5: จำนวนเงิน (บาท) | I5: ค่าแรงงาน (บาท)
A6: 1 | B6: งานโครงสร้างวิศวกรรม
B7: 1.1 งานดิน หิน ทราย และฐานราก
B8: - ขุดดินฐานรากและถมคืน (งานแบ็คโคร) | C8: =(หลังริม!C8*1)+(หลังกลาง!C8*6) -> 11.666667 | D8: วัน | E8: 3500 | F8: =E8*C8 -> 40833.333 | G8: 0 | H8: =G8*E8 -> 0 | I8: =H8+F8 -> 40833.333
B9: - คอนกรีตผสมเสร็จ 280 กก./ตร.ซม. (ลูกบาศก์) | C9: =(หลังริม!C9*1)+(หลังกลาง!C9*6) -> 6.4166667 | D9: ลบ.ม. | E9: 1500 | F9: =E9*C9 -> 9625 | G9: 1 | H9: =G9*E9 -> 1500 | I9: =H9+F9 -> 11125
B10: - คอนกรีตหยาบรองก้นฐานราก 1:3:5 | C10: =(หลังริม!C10*1)+(หลังกลาง!C10*6) -> 0 | D10: ลบ.ม. | E10: 0 | F10: =E10*C10 -> 0 | G10: 2 | H10: =G10*E10 -> 0 | I10: =H10+F10 -> 0
B11: - ทรายถมปรับระดับ | C11: =(หลังริม!C11*1)+(หลังกลาง!C11*6) -> 46.666667 | D11: ลบ.ม. | E11: 100 | F11: =E11*C11 -> 4666.6667 | G11: 3 | H11: =G11*E11 -> 300 | I11: =H11+F11 -> 4966.6667
B12: รวมงานข้อ 1.1 | C12: =(หลังริม!C12*1)+(หลังกลาง!C12*6) -> 0 | F12: =SUM(F8:F11) -> 55125 | H12: =SUM(H8:H11) -> 1800 | I12: =SUM(I8:I11) -> 56925 | K12: =H12+F12 -> 56925
B13: 1.2 งานตอกเสาเข็ม | C13: =(หลังริม!C13*1)+(หลังกลาง!C13*6) -> 0
B14: - เสาเข็ม ไอตัน ขนาด 0.18 x 0.18 x 16 ม. | C14: =(หลังริม!C14*1)+(หลังกลาง!C14*6) -> 61.833333 | D14: ต้น | E14: 2080 | F14: =E14*C14 -> 128613.33 | G14: 750 | H14: =G14*C14 -> 46375 | I14: =H14+F14 -> 174988.33
B15: - ค่าสกัดหัวเสาเข็ม | C15: =(หลังริม!C15*1)+(หลังกลาง!C15*6) -> 0 | D15: ต้น | E15: 0 | F15: =E15*C15 -> 0 | G15: 0 | H15: =G15*C15 -> 0 | I15: =H15+F15 -> 0
B16: รวมงานข้อ 1.2 | C16: =(หลังริม!C16*1)+(หลังกลาง!C16*6) -> 0 | F16: =SUM(F14:F15) -> 128613.33 | H16: =SUM(H14:H15) -> 46375 | I16: =SUM(I14:I15) -> 174988.33 | K16: =H16+F16 -> 174988.33
B17: 1.3 งานแบบหล่อคอนกรีต | C17: =(หลังริม!C17*1)+(หลังกลาง!C17*6) -> 0
B18: - ไม้แบบทั่วไป | C18: =(หลังริม!C18*1)+(หลังกลาง!C18*6) -> 23.333333 | D18: แผ่น | E18: 590 | F18: =E18*C18 -> 13766.667 | G18: 0 | H18: =G18*E18 -> 0 | I18: =H18+F18 -> 13766.667
B19: - ไม้คร่าว | C19: =(หลังริม!C19*1)+(หลังกลาง!C19*6) -> 0 | D19: ลบ.ฟ. | E19: 0 | F19: =E19*C19 -> 0 | G19: 0 | H19: =G19*E19 -> 0 | I19: =H19+F19 -> 0
B20: - ไม้ค้ำยัน | C20: =(หลังริม!C20*1)+(หลังกลาง!C20*6) -> 233.33333 | D20: ต้น | E20: 25 | F20: =E20*C20 -> 5833.3333 | G20: 0 | H20: =G20*E20 -> 0 | I20: =H20+F20 -> 5833.3333
B21: - ตะปูขนาดต่างๆ | C21: =(หลังริม!C21*1)+(หลังกลาง!C21*6) -> 0 | D21: กก. | E21: 0 | F21: =E21*C21 -> 0 | G21: 0 | H21: =G21*E21 -> 0 | I21: =H21+F21 -> 0
B22: - ค่าแรงงานไม้แบบ | C22: =(หลังริม!C22*1)+(หลังกลาง!C22*6) -> 0 | D22: ตร.ม. | E22: 0 | F22: =E22*C22 -> 0 | G22: 0 | H22: =G22*E22 -> 0 | I22: =H22+F22 -> 0
B23: รวมงานข้อ 1.3 | C23: =(หลังริม!C23*1)+(หลังกลาง!C23*6) -> 0 | F23: =SUM(F18:F22) -> 19600 | H23: =SUM(H18:H22) -> 0 | I23: =SUM(I18:I22) -> 19600 | K23: =H23+F23 -> 19600
B24: 1.4 งานคอนกรีตโครงสร้าง | C24: =(หลังริม!C24*1)+(หลังกลาง!C24*6) -> 0
B25: - คอนกรีตหยาบ( lean) | C25: =(หลังริม!C25*1)+(หลังกลาง!C25*6) -> 17.5 | D25: ลบ.ม. | E25: 1300 | F25: =E25*C25 -> 22750 | G25: 0 | H25: =G25*C25 -> 0 | I25: =H25+F25 -> 22750
B26: - คอนกรีตผสมเสร็จ 280 กก./ตร.ซม. (ลูกบาศก์) | C26: =(หลังริม!C26*1)+(หลังกลาง!C26*6) -> 64.166667 | D26: ลบ.ม. | E26: 1500 | F26: =E26*C26 -> 96250 | G26: 0 | H26: =G26*C26 -> 0 | I26: =H26+F26 -> 96250
B27: - คอนกรีตผสมเสร็จ 320 กก./ตร.ซม. (ลูกบาศก์) | C27: =(หลังริม!C27*1)+(หลังกลาง!C27*6) -> 0 | D27: ลบ.ม. | E27: 1600 | F27: =E27*C27 -> 0 | G27: 0 | H27: =G27*C27 -> 0 | I27: =H27+F27 -> 0
B28: - เหล็กตะแกรง WIRE MESH Ø 6 มม. @ 0.20 ม. (ข้ออ้อย) | C28: =(หลังริม!C28*1)+(หลังกลาง!C28*6) -> 700 | D28: ตร.ม. | E28: 74.2 | F28: =E28*C28 -> 51940 | G28: 0 | H28: =G28*C28 -> 0 | I28: =H28+F28 -> 51940
B29: - ค่าแรงงานโครงสร้าง | C29: =(หลังริม!C29*1)+(หลังกลาง!C29*6) -> 700 | D29: ตร.ม. | E29: 0 | F29: =E29*C29 -> 0 | G29: 173.47 | H29: =G29*C29 -> 121429 | I29: =H29+F29 -> 121429
B30: รวมงานข้อ 1.4 | C30: =(หลังริม!C30*1)+(หลังกลาง!C30*6) -> 0 | F30: =SUM(F25:F29) -> 170940 | H30: =SUM(H25:H29) -> 121429 | I30: =SUM(I25:I29) -> 292369 | K30: =H30+F30 -> 292369
B31: 1.5 งานเหล็กเสริมคอนกรีต | C31: =(หลังริม!C31*1)+(หลังกลาง!C31*6) -> 0
B32: - เหล็กเส้นกลมผิวเรียบ SR 24 ขนาด Ø 6 มม. | C32: =(หลังริม!C32*1)+(หลังกลาง!C32*6) -> 0.1295 | D32: ตัน | E32: 64 | F32: =C32*1000/2.22*E32 -> 3733.3333 | G32: 0 | H32: =G32*C32 -> 0 | I32: =H32+F32 -> 3733.3333
B33: - เหล็กเส้นกลมผิวเรียบ SR 24 ขนาด Ø 9 มม. | C33: =(หลังริม!C33*1)+(หลังกลาง!C33*6) -> 0.37840833 | D33: ตัน | E33: 137 | F33: =C33*1000/4.99*E33 -> 10389.167 | G33: 0 | H33: =G33*C33 -> 0 | I33: =H33+F33 -> 10389.167
B34: - เหล็กเส้นกลมผิวข้ออ้อย SD 40 ขนาด Ø 12 มม. | C34: =(หลังริม!C34*1)+(หลังกลาง!C34*6) -> 2.2274 | D34: ตัน | E34: 240 | F34: =C34*1000/8.88*E34 -> 60200 | G34: 0 | H34: =G34*C34 -> 0 | I34: =H34+F34 -> 60200
B35: - เหล็กเส้นกลมผิวข้ออ้อย SD 40 ขนาด Ø 16 มม. | C35: =(หลังริม!C35*1)+(หลังกลาง!C35*6) -> 0 | D35: ตัน | E35: 425 | F35: =C35*1000/15.78*E35 -> 0 | G35: 0 | H35: =G35*C35 -> 0 | I35: =H35+F35 -> 0
B36: - ลวดผูกเหล็ก Ø 1.25 มม. (เบอร์ 18) | C36: =(หลังริม!C36*1)+(หลังกลาง!C36*6) -> 0 | D36: กก. | E36: 0 | F36: =E36*C36 -> 0 | G36: 0 | H36: =G36*C36 -> 0 | I36: =H36+F36 -> 0
B37: รวมงานข้อ 1.5 | C37: =(หลังริม!C37*1)+(หลังกลาง!C37*6) -> 0 | F37: =SUM(F32:F36) -> 74322.5 | H37: =SUM(H32:H36) -> 0 | I37: =SUM(I32:I36) -> 74322.5 | K37: =H37+F37 -> 74322.5
B38: 1.6 งานผนังสำเร็จ (แบบหล่อพร้อมจับเซี้ยม) | C38: =(หลังริม!C38*1)+(หลังกลาง!C38*6) -> 0
B39: - เหล็กเส้นกลมผิวเรียบ SR 24 ขนาด Ø 9 มม. | C39: =(หลังริม!C39*1)+(หลังกลาง!C39*6) -> 0.34883333 | D39: ตัน | E39: 137 | F39: =C39*1000/4.99*E39 -> 9577.1877 | G39: 0 | H39: =G39*C39 -> 0 | I39: =H39+F39 -> 9577.1877
B40: - เหล็กเส้นกลมผิวข้ออ้อย SD 40 ขนาด Ø 12 มม. | C40: =(หลังริม!C40*1)+(หลังกลาง!C40*6) -> 0.61833333 | D40: ตัน | E40: 240 | F40: =C40*1000/8.88*E40 -> 16711.712 | G40: 0 | H40: =G40*C40 -> 0 | I40: =H40+F40 -> 16711.712
B41: - คอนกรีตผสมเสร็จ 280 กก./ตร.ซม. (ปั้ม) | C41: =(หลังริม!C41*1)+(หลังกลาง!C41*6) -> 68.833333 | D41: ลบ.ม. | E41: 1600 | F41: =E41*C41 -> 110133.33 | G41: 0 | H41: =G41*C41 -> 0 | I41: =H41+F41 -> 110133.33
B42: - เหล็กตะแกรง WIRE MESH Ø 6 มม. @ 0.20 ม. | C42: =(หลังริม!C42*1)+(หลังกลาง!C42*6) -> 700 | D42: ตร.ม. | E42: 74.2 | F42: =E42*C42 -> 51940 | G42: 0 | H42: =G42*C42 -> 0 | I42: =H42+F42 -> 51940
...

Sheet สำนักงานขายPL
A1: BOQ สรุปรายการปริมาณงานและราคา บ้านแถวหลังริม
A4: ลำดับที่ | B4: รายการ | C4: จำนวน | D4: หน่วย | E4: ค่าวัสดุ | G4: ค่าแรงงาน | I4: รวมค่าวัสดุและ | J4: หมายเหตุ
E5: ราคาต่อหน่วย | F5: จำนวนเงิน (บาท) | G5: ราคาต่อหน่วย | H5: จำนวนเงิน (บาท) | I5: ค่าแรงงาน (บาท)
A6: 1 | B6: งานโครงสร้างวิศวกรรม
B7: 1.1 งานดิน หิน ทราย และฐานราก
B8: - ขุดดินฐานรากและถมคืน (งานแบ็คโคร) | C8: =10/6 -> 1.6666667 | D8: วัน | E8: 3500 | F8: =E8*C8 -> 5833.3333 | G8: 0 | H8: =G8*C8 -> 0 | I8: =H8+F8 -> 5833.3333
B9: - คอนกรีตผสมเสร็จ 280 กก./ตร.ซม. (ลูกบาศก์) | C9: =5.5/6 -> 0.91666667 | D9: ลบ.ม. | E9: 1500 | F9: =E9*C9 -> 1375 | G9: 0 | H9: =G9*C9 -> 0 | I9: =H9+F9 -> 1375
B10: - คอนกรีตหยาบรองก้นฐานราก 1:3:5 | C10: 0 | D10: ลบ.ม. | E10: 0 | F10: =E10*C10 -> 0 | G10: 0 | H10: =G10*C10 -> 0 | I10: =H10+F10 -> 0
B11: - ทรายถมปรับระดับ | C11: =40/6 -> 6.6666667 | D11: ลบ.ม. | E11: 100 | F11: =E11*C11 -> 666.66667 | G11: 0 | H11: =G11*C11 -> 0 | I11: =H11+F11 -> 666.66667
B12: รวมงานข้อ 1.1 | F12: =SUM(F8:F11) -> 7875 | H12: =SUM(H8:H11) -> 0 | I12: =SUM(I8:I11) -> 7875 | K12: =H12+F12 -> 7875
B13: 1.2 งานตอกเสาเข็ม
B14: - เสาเข็ม ไอตัน ขนาด 0.18 x 0.18 x 16 ม. | C14: =53/6 -> 8.8333333 | D14: ต้น | E14: 2080 | F14: =E14*C14 -> 18373.333 | G14: 750 | H14: =G14*C14 -> 6625 | I14: =H14+F14 -> 24998.333
B15: - ค่าสกัดหัวเสาเข็ม | C15: 0 | D15: ต้น | E15: 0 | F15: =E15*C15 -> 0 | G15: 0 | H15: =G15*C15 -> 0 | I15: =H15+F15 -> 0
B16: รวมงานข้อ 1.2 | F16: =SUM(F14:F15) -> 18373.333 | H16: =SUM(H14:H15) -> 6625 | I16: =SUM(I14:I15) -> 24998.333 | K16: =H16+F16 -> 24998.333
B17: 1.3 งานแบบหล่อคอนกรีต
B18: - ไม้แบบทั่วไป | C18: =20/6 -> 3.3333333 | D18: แผ่น | E18: 590 | F18: =E18*C18 -> 1966.6667 | G18: 0 | H18: =G18*C18 -> 0 | I18: =H18+F18 -> 1966.6667
B19: - ไม้คร่าว | C19: 0 | D19: ลบ.ฟ. | E19: 0 | F19: =E19*C19 -> 0 | G19: 0 | H19: =G19*C19 -> 0 | I19: =H19+F19 -> 0
B20: - ไม้ค้ำยัน | C20: =200/6 -> 33.333333 | D20: ต้น | E20: 25 | F20: =E20*C20 -> 833.33333 | G20: 0 | H20: =G20*C20 -> 0 | I20: =H20+F20 -> 833.33333
B21: - ตะปูขนาดต่างๆ | C21: 0 | D21: กก. | E21: 0 | F21: =E21*C21 -> 0 | G21: 0 | H21: =G21*C21 -> 0 | I21: =H21+F21 -> 0
B22: - ค่าแรงงานไม้แบบ | C22: 0 | D22: ตร.ม. | E22: 0 | F22: =E22*C22 -> 0 | G22: 0 | H22: =G22*C22 -> 0 | I22: =H22+F22 -> 0
B23: รวมงานข้อ 1.3 | F23: =SUM(F18:F22) -> 2800 | H23: =SUM(H18:H22) -> 0 | I23: =SUM(I18:I22) -> 2800 | K23: =H23+F23 -> 2800
B24: 1.4 งานคอนกรีตโครงสร้าง
B25: - คอนกรีตหยาบ( lean) | C25: =15/6 -> 2.5 | D25: ลบ.ม. | E25: 1300 | F25: =E25*C25 -> 3250 | G25: 0 | H25: =G25*C25 -> 0 | I25: =H25+F25 -> 3250
B26: - คอนกรีตผสมเสร็จ 280 กก./ตร.ซม. (ลูกบาศก์) | C26: =55/6 -> 9.1666667 | D26: ลบ.ม. | E26: 1500 | F26: =E26*C26 -> 13750 | G26: 0 | H26: =G26*C26 -> 0 | I26: =H26+F26 -> 13750
B27: - คอนกรีตผสมเสร็จ 320 กก./ตร.ซม. (ลูกบาศก์) | C27: 0 | D27: ลบ.ม. | E27: 1600 | F27: =E27*C27 -> 0 | G27: 0 | H27: =G27*C27 -> 0 | I27: =H27+F27 -> 0
B28: - เหล็กตะแกรง WIRE MESH Ø 6 มม. @ 0.20 ม. (ข้ออ้อย) | C28: =600/6 -> 100 | D28: ตร.ม. | E28: 74.2 | F28: =E28*C28 -> 7420 | G28: 0 | H28: =G28*C28 -> 0 | I28: =H28+F28 -> 7420
B29: - ค่าแรงงานโครงสร้าง | C29: =600/6 -> 100 | D29: ตร.ม. | E29: 0 | F29: =E29*C29 -> 0 | G29: 173.47 | H29: =G29*C29 -> 17347 | I29: =H29+F29 -> 17347
B30: รวมงานข้อ 1.4 | F30: =SUM(F25:F29) -> 24420 | H30: =SUM(H25:H29) -> 17347 | I30: =SUM(I25:I29) -> 41767 | K30: =H30+F30 -> 41767
B31: 1.5 งานเหล็กเสริมคอนกรีต
B32: - เหล็กเส้นกลมผิวเรียบ SR 24 ขนาด Ø 6 มม. | C32: =(50*2.22/1000)/6 -> 0.0185 | D32: ตัน | E32: 64 | F32: =C32*1000/2.22*E32 -> 533.33333 | G32: 0 | H32: =G32*C32 -> 0 | I32: =H32+F32 -> 533.33333
B33: - เหล็กเส้นกลมผิวเรียบ SR 24 ขนาด Ø 9 มม. | C33: =(65*4.99/1000)/6 -> 0.054058333 | D33: ตัน | E33: 137 | F33: =C33*1000/4.99*E33 -> 1484.1667 | G33: 0 | H33: =G33*C33 -> 0 | I33: =H33+F33 -> 1484.1667
B34: - เหล็กเส้นกลมผิวข้ออ้อย SD 40 ขนาด Ø 12 มม. | C34: =(215*8.88/1000)/6 -> 0.3182 | D34: ตัน | E34: 240 | F34: =C34*1000/8.88*E34 -> 8600 | G34: 0 | H34: =G34*C34 -> 0 | I34: =H34+F34 -> 8600
B35: - เหล็กเส้นกลมผิวข้ออ้อย SD 40 ขนาด Ø 16 มม. | C35: 0 | D35: ตัน | E35: 425 | F35: =C35*1000/15.78*E35 -> 0 | G35: 0 | H35: =G35*C35 -> 0 | I35: =H35+F35 -> 0
B36: - ลวดผูกเหล็ก Ø 1.25 มม. (เบอร์ 18) | C36: 0 | D36: กก. | E36: 0 | F36: =E36*C36 -> 0 | G36: 0 | H36: =G36*C36 -> 0 | I36: =H36+F36 -> 0
B37: รวมงานข้อ 1.5 | F37: =SUM(F32:F36) -> 10617.5 | H37: =SUM(H32:H36) -> 0 | I37: =SUM(I32:I36) -> 10617.5 | K37: =H37+F37 -> 10617.5
B38: 1.6 งานผนังสำเร็จ (แบบหล่อพร้อมจับเซี้ยม)
B39: - เหล็กเส้นกลมผิวเรียบ SR 24 ขนาด Ø 9 มม. | C39: =0.299/6 -> 0.049833333 | D39: ตัน | E39: 137 | F39: =C39*1000/4.99*E39 -> 1368.1697 | G39: 0 | H39: =G39*C39 -> 0 | I39: =H39+F39 -> 1368.1697
B40: - เหล็กเส้นกลมผิวข้ออ้อย SD 40 ขนาด Ø 12 มม. | C40: =0.53/6 -> 0.088333333 | D40: ตัน | E40: 240 | F40: =C40*1000/8.88*E40 -> 2387.3874 | G40: 0 | H40: =G40*C40 -> 0 | I40: =H40+F40 -> 2387.3874
B41: - คอนกรีตผสมเสร็จ 280 กก./ตร.ซม. (ปั้ม) | C41: =59/6 -> 9.8333333 | D41: ลบ.ม. | E41: 1600 | F41: =E41*C41 -> 15733.333 | G41: 0 | H41: =G41*C41 -> 0 | I41: =H41+F41 -> 15733.333
B42: - เหล็กตะแกรง WIRE MESH Ø 6 มม. @ 0.20 ม. | C42: =600/6 -> 100 | D42: ตร.ม. | E42: 74.2 | F42: =E42*C42 -> 7420 | G42: 0 | H42: =G42*C42 -> 0 | I42: =H42+F42 -> 7420
...
